Workbook

Sheet Dashboard
B2: DASHBOARD DE INVENTARIO — PANTALLAS INTERACTIVAS
B3: Resumen general y por bloque/zona (se actualiza automáticamente desde la hoja Inventario)
B5: Total Pantallas (registros) | D5: Instaladas | F5: Pendientes | H5: % Avance Instalación
B6: =COUNTA(Inventario!A2:A59) -> 58 | D6: =COUNTIF(Inventario!D2:D59,"Instalada") -> 42 | F6: =COUNTIF(Inventario!D2:D59,"Pendiente") -> 16 | H6: =D6/B6 -> 0.72413793
B9: Detalle por Bloque / Zona
B10: Bloque / Zona | C10: Total | D10: Instaladas | E10: Pendientes | F10: % Avance
B11: Bloque 1 | C11: =COUNTIF(Inventario!B2:B59,B11) -> 5 | D11: =COUNTIFS(Inventario!B2:B59,B11,Inventario!D2:D59,"Instalada") -> 5 | E11: =C11-D11 -> 0 | F11: =IF(C11=0,0,D11/C11) -> 1
B12: Bloque 2 | C12: =COUNTIF(Inventario!B2:B59,B12) -> 5 | D12: =COUNTIFS(Inventario!B2:B59,B12,Inventario!D2:D59,"Instalada") -> 5 | E12: =C12-D12 -> 0 | F12: =IF(C12=0,0,D12/C12) -> 1
B13: Bloque 3 | C13: =COUNTIF(Inventario!B2:B59,B13) -> 3 | D13: =COUNTIFS(Inventario!B2:B59,B13,Inventario!D2:D59,"Instalada") -> 3 | E13: =C13-D13 -> 0 | F13: =IF(C13=0,0,D13/C13) -> 1
B14: Bloque 4 | C14: =COUNTIF(Inventario!B2:B59,B14) -> 5 | D14: =COUNTIFS(Inventario!B2:B59,B14,Inventario!D2:D59,"Instalada") -> 0 | E14: =C14-D14 -> 5 | F14: =IF(C14=0,0,D14/C14) -> 0
B15: Bloque 5 | C15: =COUNTIF(Inventario!B2:B59,B15) -> 5 | D15: =COUNTIFS(Inventario!B2:B59,B15,Inventario!D2:D59,"Instalada") -> 1 | E15: =C15-D15 -> 4 | F15: =IF(C15=0,0,D15/C15) -> 0.2
B16: Bloque 6 | C16: =COUNTIF(Inventario!B2:B59,B16) -> 5 | D16: =COUNTIFS(Inventario!B2:B59,B16,Inventario!D2:D59,"Instalada") -> 1 | E16: =C16-D16 -> 4 | F16: =IF(C16=0,0,D16/C16) -> 0.2
B17: Bloque 7 | C17: =COUNTIF(Inventario!B2:B59,B17) -> 3 | D17: =COUNTIFS(Inventario!B2:B59,B17,Inventario!D2:D59,"Instalada") -> 2 | E17: =C17-D17 -> 1 | F17: =IF(C17=0,0,D17/C17) -> 0.66666667
B18: Bloque 8 | C18: =COUNTIF(Inventario!B2:B59,B18) -> 2 | D18: =COUNTIFS(Inventario!B2:B59,B18,Inventario!D2:D59,"Instalada") -> 2 | E18: =C18-D18 -> 0 | F18: =IF(C18=0,0,D18/C18) -> 1
B19: Bloque 9 | C19: =COUNTIF(Inventario!B2:B59,B19) -> 2 | D19: =COUNTIFS(Inventario!B2:B59,B19,Inventario!D2:D59,"Instalada") -> 2 | E19: =C19-D19 -> 0 | F19: =IF(C19=0,0,D19/C19) -> 1
B20: CEP | C20: =COUNTIF(Inventario!B2:B59,B20) -> 10 | D20: =COUNTIFS(Inventario!B2:B59,B20,Inventario!D2:D59,"Instalada") -> 10 | E20: =C20-D20 -> 0 | F20: =IF(C20=0,0,D20/C20) -> 1
B21: Derecho | C21: =COUNTIF(Inventario!B2:B59,B21) -> 7 | D21: =COUNTIFS(Inventario!B2:B59,B21,Inventario!D2:D59,"Instalada") -> 7 | E21: =C21-D21 -> 0 | F21: =IF(C21=0,0,D21/C21) -> 1
B22: Idiomas | C22: =COUNTIF(Inventario!B2:B59,B22) -> 2 | D22: =COUNTIFS(Inventario!B2:B59,B22,Inventario!D2:D59,"Instalada") -> 2 | E22: =C22-D22 -> 0 | F22: =IF(C22=0,0,D22/C22) -> 1
B23: Otros | C23: =COUNTIF(Inventario!B2:B59,B23) -> 4 | D23: =COUNTIFS(Inventario!B2:B59,B23,Inventario!D2:D59,"Instalada") -> 2 | E23: =C23-D23 -> 2 | F23: =IF(C23=0,0,D23/C23) -> 0.5

Sheet Inventario
A1: ID | B1: Bloque / Zona | C1: Salón | D1: Estado | E1: Pulgadas | F1: Activo Fijo Pantalla | G1: Serial Pantalla | H1: Modelo | I1: Accesorios | J1: Fecha Instalación | K1: Fecha Iceberg | L1: Serial OPS | M1: Características OPS | N1: Fecha OPS | O1: Activo Fijo UPS | P1: Año
A2: 1 | B2: Bloque 1 | C2: 1-11 | D2: Instalada | E2: 65" | F2: U15280502555 | G2: OS99T7250300044 | H2: T7-65 | I2: 1 cable HDMI, 1 cable de alimentación, 1 cable táctil | J2: 2025-07-28 | K2: 2025-08-04 | L2: OSOPSI711L703980J | M2: i7 - 16 GB - 256 GB | N2: 2025-07-28 | O2: U15280502554 | P2: 2025
A3: 2 | B3: Bloque 1 | C3: 1-12 | D3: Instalada | E3: 65" | F3: U15280502429 | G3: OS68TL7240700747 | H3: TL7-65 | I3: 2 cable HDMI, 1 cable de alimentación, 1 cable táctil | J3: 2025-04-14 | K3: 2025-03-18 | L3: MCS-20241225004 | M3: i7 - 16 GB - 256 GB | N3: 2025-04-14 | O3: U15280503767 | P3: 2025
A4: 3 | B4: Bloque 1 | C4: 1-13 | D4: Instalada | E4: 65" | F4: U15280502430 | G4: OS68TL7240700637 | H4: TL7-65 | I4: 3 cable HDMI, 1 cable de alimentación, 1 cable táctil | J4: 2025-04-14 | K4: 2025-03-18 | L4: MCS-20241225019 | M4: i7 - 16 GB - 256 GB | N4: 2025-04-14 | O4: U15280503775 | P4: 2025
A5: 4 | B5: Bloque 1 | C5: 1-14 | D5: Instalada | E5: 65" | F5: U15280503723 | G5: OS68TL7240300717 | H5: TL7-65 | I5: 4 cable HDMI, 1 cable de alimentación, 1 cable táctil | J5: 2024-12-05 | K5: 2024-08-21 | L5: OSOPSI512L700177J | M5: i5 - 8GB - 256 GB | N5: 2024-12-05 | O5: U15280503744 | P5: 2024
A6: 5 | B6: Bloque 1 | C6: 1-15 | D6: Instalada | E6: 65" | F6: U15280503722 | G6: OS68TL7240300500 | H6: TL7-65 | I6: 5 cable HDMI, 1 cable de alimentación, 1 cable táctil | J6: 2024-12-07 | K6: 2024-08-21 | L6: OSOPSI512L700137J | M6: i5 - 8GB - 256 GB | N6: 2024-12-07 | O6: U15280509717 | P6: 2024
A7: 6 | B7: Bloque 2 | C7: 2-11 | D7: Instalada | E7: 86" | F7: U15280502431 | G7: OS68T7240900168 | H7: T7-86 | I7: 6 cable HDMI, 1 cable de alimentación, 1 cable táctil | J7: 2025-04-14 | K7: 2025-03-18 | L7: MCS-20241225017 | M7: i7 - 16 GB - 256 GB | N7: 2025-04-14 | O7: U15280503762 | P7: 2025
A8: 7 | B8: Bloque 2 | C8: 2-12 | D8: Instalada | E8: 75" | F8: U15280503800 | G8: OS99T7250300186 | H8: T7-75 | I8: 7 cable HDMI, 1 cable de alimentación, 1 cable táctil | J8: 2025-07-17 | K8: 2025-07-17 | L8: OSOPSI711L704103J | M8: i7 - 16 GB - 256 GB | N8: 2025-07-17 | O8: U15200503606 | P8: 2025
A9: 8 | B9: Bloque 2 | C9: 2-13 | D9: Instalada | E9: 75" | F9: U15280502571 | G9: OS99T7250300240 | H9: T7-75 | I9: 8 cable HDMI, 1 cable de alimentación, 1 cable táctil | J9: 2025-11-07 | K9: 2025-11-18 | L9: OSOPSI711L704323J | M9: i7 - 16 GB - 256 GB | N9: 2025-11-07 | O9: U15200503639 | P9: 2025
A10: 9 | B10: Bloque 2 | C10: 2-17 | D10: Instalada | E10: 86" | F10: U15280503732 | G10: OS99T7240700921 | H10: T7-86 | I10: 9 cable HDMI, 1 cable de alimentación, 1 cable táctil | J10: 2024-12-07 | K10: 2024-08-21 | L10: OSOPSI512L700151J | M10: i5 - 8GB - 256 GB | N10: 2024-12-07 | O10: U15280503745 | P10: 2024
A11: 10 | B11: Bloque 2 | C11: 2-18 | D11: Instalada | E11: 86" | F11: U15280502432 | G11: OS68T7240900102 | H11: T7-86 | I11: 10 cable HDMI, 1 cable de alimentación, 1 cable táctil | J11: 2025-04-14 | K11: 2025-03-18 | L11: MCS-20241225010 | M11: i7 - 16 GB - 256 GB | N11: 2025-04-14 | O11: U15280503772 | P11: 2025
A12: 11 | B12: Bloque 3 | C12: 3-12 | D12: Instalada | E12: 75" | F12: U15280502574 | G12: OS99T7250300370 | H12: T7-75 | I12: 11 cable HDMI, 1 cable de alimentación, 1 cable táctil | J12: 2025-11-07 | K12: 2025-11-18 | L12: OSOPSI711L703254J | M12: i7 - 16 GB - 256 GB | N12: 2025-11-07 | O12: U15200503640 | P12: 2025
A13: 12 | B13: Bloque 3 | C13: 3-13 | D13: Instalada | E13: 86" | F13: U15280503733 | G13: OS99T7240700963 | H13: T7-86 | I13: 12 cable HDMI, 1 cable de alimentación, 1 cable táctil | J13: 2024-12-06 | K13: 2024-08-21 | L13: OSOPSI512L700107J | M13: i5 - 8GB - 256 GB | N13: 2024-12-06 | O13: U15280503718 | P13: 2024
A14: 13 | B14: Bloque 3 | C14: 3-14 | D14: Instalada | E14: 75" | F14: U15280502572 | G14: OS99T7250300334 | H14: T7-75 | I14: 13 cable HDMI, 1 cable de alimentación, 1 cable táctil | J14: 2025-11-07 | K14: 2025-11-18 | L14: OSOPSI711L704102J | M14: i7 - 16 GB - 256 GB | N14: 2025-11-07 | O14: U15200503638 | P14: 2025
A15: 14 | B15: Bloque 4 | C15: 4-11 | D15: Pendiente | E15: 75" | H15: T7-75 | I15: 14 cable HDMI, 1 cable de alimentación, 1 cable táctil | J15: 2026-07-27 | N15: 2026-07-27 | P15: 2026
A16: 15 | B16: Bloque 4 | C16: 4-12 | D16: Pendiente | E16: 75" | H16: T7-75 | I16: 15 cable HDMI, 1 cable de alimentación, 1 cable táctil | J16: 2026-07-27 | N16: 2026-07-27 | P16: 2026
A17: 16 | B17: Bloque 4 | C17: 4-13 | D17: Pendiente | E17: 75" | H17: T7-75 | I17: 16 cable HDMI, 1 cable de alimentación, 1 cable táctil | J17: 2026-07-27 | N17: 2026-07-27 | P17: 2026
A18: 17 | B18: Bloque 4 | C18: 4-14 | D18: Pendiente | E18: 75" | H18: T7-75 | I18: 17 cable HDMI, 1 cable de alimentación, 1 cable táctil | J18: 2026-07-27 | N18: 2026-07-27 | P18: 2026
A19: 18 | B19: Bloque 4 | C19: 4-15 | D19: Pendiente | E19: 75" | H19: T7-75 | I19: 18 cable HDMI, 1 cable de alimentación, 1 cable táctil | J19: 2026-07-27 | N19: 2026-07-27 | P19: 2026
A20: 19 | B20: Bloque 5 | C20: 5-11 | D20: Pendiente | E20: 75" | H20: T7-75 | I20: 19 cable HDMI, 1 cable de alimentación, 1 cable táctil | J20: 2026-07-27 | N20: 2026-07-27 | P20: 2026
A21: 20 | B21: Bloque 5 | C21: 5-12 | D21: Pendiente | E21: 75" | H21: T7-75 | I21: 20 cable HDMI, 1 cable de alimentación, 1 cable táctil | J21: 2026-07-27 | N21: 2026-07-27 | P21: 2026
A22: 21 | B22: Bloque 5 | C22: 5-13 | D22: Pendiente | E22: 75" | H22: T7-75 | I22: 21 cable HDMI, 1 cable de alimentación, 1 cable táctil | J22: 2026-07-27 | N22: 2026-07-27 | P22: 2026
A23: 22 | B23: Bloque 5 | C23: 5-14 | D23: Instalada | E23: 75" | F23: U15280502570 | G23: OS99T7250300156 | H23: T7-75 | I23: 22 cable HDMI, 1 cable de alimentación, 1 cable táctil | J23: 2025-11-07 | K23: 2025-11-18 | L23: OSOPSI711L703255J | M23: i7 - 16 GB - 256 GB | N23: 2025-11-07 | O23: U15200503637 | P23: 2025
A24: 23 | B24: Bloque 5 | C24: 5-15 | D24: Pendiente | E24: 75" | H24: T7-75 | I24: 23 cable HDMI, 1 cable de alimentación, 1 cable táctil | J24: 2026-07-27 | N24: 2026-07-27 | P24: 2026
A25: 24 | B25: Bloque 6 | C25: 6-11 | D25: Instalada | E25: 65" | F25: U15280502551 | G25: YN200061G07150098 | H25: T6-65 | I25: 24 cable HDMI, 1 cable de alimentación, 1 cable táctil | J25: 2022-01-01 | K25: 2022-10-15 | L25: YW190064F03010074 | M25: i3 - 8GB - 512 GB | N25: 2024-01-01 | O25: U15280502366 | P25: 2022
A26: 25 | B26: Bloque 6 | C26: 6-12 | D26: Pendiente | E26: 75" | H26: T7-75 | I26: 25 cable HDMI, 1 cable de alimentación, 1 cable táctil | J26: 2026-07-27 | N26: 2026-07-27 | P26: 2026
A27: 26 | B27: Bloque 6 | C27: 6-13 | D27: Pendiente | E27: 75" | H27: T7-75 | I27: 26 cable HDMI, 1 cable de alimentación, 1 cable táctil | J27: 2026-07-27 | N27: 2026-07-27 | P27: 2026
A28: 27 | B28: Bloque 6 | C28: 6-14 | D28: Pendiente | E28: 75" | H28: T7-75 | I28: 27 cable HDMI, 1 cable de alimentación, 1 cable táctil | J28: 2026-07-27 | N28: 2026-07-27 | P28: 2026
A29: 28 | B29: Bloque 6 | C29: 6-15 | D29: Pendiente | E29: 75" | H29: T7-75 | I29: 28 cable HDMI, 1 cable de alimentación, 1 cable táctil | J29: 2026-07-27 | N29: 2026-07-27 | P29: 2026
A30: 29 | B30: Bloque 7 | C30: 7-12 | D30: Instalada | E30: 75" | F30: U15280503798 | G30: OS99T7250300164 | H30: T7-75 | I30: 29 cable HDMI, 1 cable de alimentación, 1 cable táctil | J30: 2025-07-14 | K30: 2025-07-18 | L30: OSOPSI711L704072J | M30: i7 - 16 GB - 256 GB | N30: 2025-07-14 | P30: 2025
A31: 30 | B31: Bloque 7 | C31: 7-13 | D31: Instalada | E31: 86" | F31: U15280502442 | G31: OS68T7240900182 | H31: T7-86 | I31: 30 cable HDMI, 1 cable de alimentación, 1 cable táctil | J31: 2025-04-14 | K31: 2025-03-18 | L31: MCS-20241225005 | M31: i7 - 16 GB - 256 GB | N31: 2025-04-14 | O31: U15280503774 | P31: 2025
A32: 31 | B32: Bloque 7 | C32: 7-14 | D32: Pendiente | E32: 75" | G32: OS99T7250300233 | H32: T7-75 | I32: 31 cable HDMI, 1 cable de alimentación, 1 cable táctil | J32: 2025-09-15 | L32: OSOPSI711L704167J | M32: i7 - 16 GB - 256 GB | N32: 2025-09-15 | P32: 2025
A33: 32 | B33: Bloque 8 | C33: 8-11 | D33: Instalada | E33: 86" | F33: U15280502434 | G33: OS68T7240900020 | H33: T7-86 | I33: 32 cable HDMI, 1 cable de alimentación, 1 cable táctil | J33: 2025-04-14 | K33: 2025-03-18 | L33: MCS-20241225007 | M33: i7 - 16 GB - 256 GB | N33: 2025-04-14 | O33: U15280503768 | P33: 2025
A34: 33 | B34: Bloque 8 | C34: 8-21 | D34: Instalada | E34: 75" | F34: U15280503799 | G34: OS99T7250300189 | H34: T7-75 | I34: 33 cable HDMI, 1 cable de alimentación, 1 cable táctil | J34: 2025-07-17 | K34: 2025-07-18 | L34: OSOPSI711L703473J | M34: i7 - 16 GB - 256 GB | N34: 2025-07-17 | P34: 2025
A35: 34 | B35: Bloque 9 | C35: 9-22 | D35: Instalada | E35: 65" | F35: U15280502436 | G35: OS99TL7240700143 | H35: TL7-65 | I35: 34 cable HDMI, 1 cable de alimentación, 1 cable táctil | J35: 2025-04-14 | K35: 2025-03-18 | L35: MCS-20241225001 | M35: i7 - 16 GB - 256 GB | N35: 2025-04-14 | O35: U15280503766 | P35: 2025
A36: 35 | B36: Bloque 9 | C36: 9-26 | D36: Instalada | E36: 75" | F36: U15280502573 | G36: OS99T7250300265 | H36: T7-75 | I36: 35 cable HDMI, 1 cable de alimentación, 1 cable táctil | J36: 2025-11-07 | K36: 2025-11-18 | L36: OSOPSI711L703925J | M36: i7 - 16 GB - 256 GB | N36: 2025-11-07 | O36: U15200503636 | P36: 2025
A37: 36 | B37: CEP | C37: CEP-17 | D37: Instalada | E37: 65" | F37: U15280502435 | G37: OS68TL7240700746 | H37: TL7-65 | I37: 36 cable HDMI, 1 cable de alimentación, 1 cable táctil | J37: 2025-04-14 | K37: 2025-03-18 | L37: MCS-20241225009 | M37: i7 - 16 GB - 256 GB | N37: 2025-04-14 | O37: U15280503764 | P37: 2025
A38: 37 | B38: CEP | C38: CEP-21 | D38: Instalada | E38: 65" | F38: U15280502550 | G38: OS99TL7240700067 | H38: TL7-65 | I38: 37 cable HDMI, 1 cable de alimentación, 1 cable táctil | J38: 2025-06-04 | K38: 2025-03-18 | L38: MCS-20241225016 | M38: i7 - 16 GB - 256 GB | N38: 2025-04-14 | O38: U15280503763 | P38: 2025
A39: 38 | B39: CEP | C39: CEP-22 | D39: Instalada | E39: 65" | F39: U15280502437 | G39: OS68TL7240700792 | H39: TL7-65 | I39: 38 cable HDMI, 1 cable de alimentación, 1 cable táctil | J39: 2025-04-14 | K39: 2025-03-18 | L39: MCS-20241225020 | M39: i7 - 16 GB - 256 GB | N39: 2025-04-14 | O39: U15280503770 | P39: 2025
A40: 39 | B40: CEP | C40: CEP-23 | D40: Instalada | E40: 65" | F40: U15280502440 | G40: OS68TL7240700703 | H40: TL7-65 | I40: 39 cable HDMI, 1 cable de alimentación, 1 cable táctil | J40: 2025-04-14 | K40: 2025-03-18 | L40: MCS-20241225018 | M40: i7 - 16 GB - 256 GB | N40: 2025-04-14 | O40: U15280503771 | P40: 2025
...
